Traceback (most recent call last):
  File "/Users/anishanand/.pyenv/versions/3.10.13/lib/python3.10/site-packages/sklearn/utils/_encode.py", line 235, in _encode
    return _map_to_integer(values, uniques)
  File "/Users/anishanand/.pyenv/versions/3.10.13/lib/python3.10/site-packages/sklearn/utils/_encode.py", line 174, in _map_to_integer
    return xp.asarray([table[v] for v in values], device=device(values))
  File "/Users/anishanand/.pyenv/versions/3.10.13/lib/python3.10/site-packages/sklearn/utils/_encode.py", line 174, in <listcomp>
    return xp.asarray([table[v] for v in values], device=device(values))
  File "/Users/anishanand/.pyenv/versions/3.10.13/lib/python3.10/site-packages/sklearn/utils/_encode.py", line 167, in __missing__
    raise KeyError(key)
KeyError: 'High'

During handling of the above exception, another exception occurred:

Traceback (most recent call last):
  File "/Users/anishanand/JeevaFitApp/lightSgd/incremental.py", line 55, in <module>
    incremental_train_sgd(
  File "/Users/anishanand/JeevaFitApp/lightSgd/incremental.py", line 38, in incremental_train_sgd
    y_new = le_risk.transform(new_df["Risk_Category"])
  File "/Users/anishanand/.pyenv/versions/3.10.13/lib/python3.10/site-packages/sklearn/preprocessing/_label.py", line 134, in transform
    return _encode(y, uniques=self.classes_)
  File "/Users/anishanand/.pyenv/versions/3.10.13/lib/python3.10/site-packages/sklearn/utils/_encode.py", line 237, in _encode
    raise ValueError(f"y contains previously unseen labels: {str(e)}")
ValueError: y contains previously unseen labels: 'High'
[INFO] Current working directory: /Users/anishanand/JeevaFitApp/lightSgd
[INFO] Training started at 2025-05-23 18:54:01.327534
Traceback (most recent call last):
  File "/Users/anishanand/.pyenv/versions/3.10.13/lib/python3.10/site-packages/sklearn/utils/_encode.py", line 235, in _encode
    return _map_to_integer(values, uniques)
  File "/Users/anishanand/.pyenv/versions/3.10.13/lib/python3.10/site-packages/sklearn/utils/_encode.py", line 174, in _map_to_integer
    return xp.asarray([table[v] for v in values], device=device(values))
  File "/Users/anishanand/.pyenv/versions/3.10.13/lib/python3.10/site-packages/sklearn/utils/_encode.py", line 174, in <listcomp>
    return xp.asarray([table[v] for v in values], device=device(values))
  File "/Users/anishanand/.pyenv/versions/3.10.13/lib/python3.10/site-packages/sklearn/utils/_encode.py", line 167, in __missing__
    raise KeyError(key)
KeyError: 'High'

During handling of the above exception, another exception occurred:

Traceback (most recent call last):
  File "/Users/anishanand/JeevaFitApp/lightSgd/incremental.py", line 49, in <module>
    incremental_train_sgd(
  File "/Users/anishanand/JeevaFitApp/lightSgd/incremental.py", line 35, in incremental_train_sgd
    y_new = le_risk.transform(new_df["Risk_Category"])
  File "/Users/anishanand/.pyenv/versions/3.10.13/lib/python3.10/site-packages/sklearn/preprocessing/_label.py", line 134, in transform
    return _encode(y, uniques=self.classes_)
  File "/Users/anishanand/.pyenv/versions/3.10.13/lib/python3.10/site-packages/sklearn/utils/_encode.py", line 237, in _encode
    raise ValueError(f"y contains previously unseen labels: {str(e)}")
ValueError: y contains previously unseen labels: 'High'
[INFO] Current working directory: /Users/anishanand/JeevaFitApp/lightSgd
[INFO] Training started at 2025-05-23 18:56:03.547212
Traceback (most recent call last):
  File "/Users/anishanand/.pyenv/versions/3.10.13/lib/python3.10/site-packages/sklearn/utils/_encode.py", line 235, in _encode
    return _map_to_integer(values, uniques)
  File "/Users/anishanand/.pyenv/versions/3.10.13/lib/python3.10/site-packages/sklearn/utils/_encode.py", line 174, in _map_to_integer
    return xp.asarray([table[v] for v in values], device=device(values))
  File "/Users/anishanand/.pyenv/versions/3.10.13/lib/python3.10/site-packages/sklearn/utils/_encode.py", line 174, in <listcomp>
    return xp.asarray([table[v] for v in values], device=device(values))
  File "/Users/anishanand/.pyenv/versions/3.10.13/lib/python3.10/site-packages/sklearn/utils/_encode.py", line 167, in __missing__
    raise KeyError(key)
KeyError: 'High'

During handling of the above exception, another exception occurred:

Traceback (most recent call last):
  File "/Users/anishanand/JeevaFitApp/lightSgd/incremental.py", line 60, in <module>
    incremental_train_sgd(
  File "/Users/anishanand/JeevaFitApp/lightSgd/incremental.py", line 37, in incremental_train_sgd
    y_new = le_risk.transform(new_df["Risk_Category"])
  File "/Users/anishanand/.pyenv/versions/3.10.13/lib/python3.10/site-packages/sklearn/preprocessing/_label.py", line 134, in transform
    return _encode(y, uniques=self.classes_)
  File "/Users/anishanand/.pyenv/versions/3.10.13/lib/python3.10/site-packages/sklearn/utils/_encode.py", line 237, in _encode
    raise ValueError(f"y contains previously unseen labels: {str(e)}")
ValueError: y contains previously unseen labels: 'High'
[INFO] Current working directory: /Users/anishanand/JeevaFitApp/lightSgd
[INFO] Training started at 2025-05-23 18:58:03.348345
Traceback (most recent call last):
  File "/Users/anishanand/.pyenv/versions/3.10.13/lib/python3.10/site-packages/sklearn/utils/_encode.py", line 235, in _encode
    return _map_to_integer(values, uniques)
  File "/Users/anishanand/.pyenv/versions/3.10.13/lib/python3.10/site-packages/sklearn/utils/_encode.py", line 174, in _map_to_integer
    return xp.asarray([table[v] for v in values], device=device(values))
  File "/Users/anishanand/.pyenv/versions/3.10.13/lib/python3.10/site-packages/sklearn/utils/_encode.py", line 174, in <listcomp>
    return xp.asarray([table[v] for v in values], device=device(values))
  File "/Users/anishanand/.pyenv/versions/3.10.13/lib/python3.10/site-packages/sklearn/utils/_encode.py", line 167, in __missing__
    raise KeyError(key)
KeyError: nan

During handling of the above exception, another exception occurred:

Traceback (most recent call last):
  File "/Users/anishanand/JeevaFitApp/lightSgd/incremental.py", line 60, in <module>
    incremental_train_sgd(
  File "/Users/anishanand/JeevaFitApp/lightSgd/incremental.py", line 37, in incremental_train_sgd
    y_new = le_risk.transform(new_df["Risk_Category"])
  File "/Users/anishanand/.pyenv/versions/3.10.13/lib/python3.10/site-packages/sklearn/preprocessing/_label.py", line 134, in transform
    return _encode(y, uniques=self.classes_)
  File "/Users/anishanand/.pyenv/versions/3.10.13/lib/python3.10/site-packages/sklearn/utils/_encode.py", line 237, in _encode
    raise ValueError(f"y contains previously unseen labels: {str(e)}")
ValueError: y contains previously unseen labels: nan
[INFO] Current working directory: /Users/anishanand/JeevaFitApp/lightSgd
[INFO] Training started at 2025-05-23 19:00:03.169012
Traceback (most recent call last):
  File "/Users/anishanand/.pyenv/versions/3.10.13/lib/python3.10/site-packages/sklearn/utils/_encode.py", line 235, in _encode
    return _map_to_integer(values, uniques)
  File "/Users/anishanand/.pyenv/versions/3.10.13/lib/python3.10/site-packages/sklearn/utils/_encode.py", line 174, in _map_to_integer
    return xp.asarray([table[v] for v in values], device=device(values))
  File "/Users/anishanand/.pyenv/versions/3.10.13/lib/python3.10/site-packages/sklearn/utils/_encode.py", line 174, in <listcomp>
    return xp.asarray([table[v] for v in values], device=device(values))
  File "/Users/anishanand/.pyenv/versions/3.10.13/lib/python3.10/site-packages/sklearn/utils/_encode.py", line 167, in __missing__
    raise KeyError(key)
KeyError: nan

During handling of the above exception, another exception occurred:

Traceback (most recent call last):
  File "/Users/anishanand/JeevaFitApp/lightSgd/incremental.py", line 60, in <module>
    incremental_train_sgd(
  File "/Users/anishanand/JeevaFitApp/lightSgd/incremental.py", line 37, in incremental_train_sgd
    y_new = le_risk.transform(new_df["Risk_Category"])
  File "/Users/anishanand/.pyenv/versions/3.10.13/lib/python3.10/site-packages/sklearn/preprocessing/_label.py", line 134, in transform
    return _encode(y, uniques=self.classes_)
  File "/Users/anishanand/.pyenv/versions/3.10.13/lib/python3.10/site-packages/sklearn/utils/_encode.py", line 237, in _encode
    raise ValueError(f"y contains previously unseen labels: {str(e)}")
ValueError: y contains previously unseen labels: nan
[INFO] Current working directory: /Users/anishanand/JeevaFitApp/lightSgd
[INFO] Training started at 2025-05-23 19:02:03.062467
Traceback (most recent call last):
  File "/Users/anishanand/.pyenv/versions/3.10.13/lib/python3.10/site-packages/sklearn/utils/_encode.py", line 235, in _encode
    return _map_to_integer(values, uniques)
  File "/Users/anishanand/.pyenv/versions/3.10.13/lib/python3.10/site-packages/sklearn/utils/_encode.py", line 174, in _map_to_integer
    return xp.asarray([table[v] for v in values], device=device(values))
  File "/Users/anishanand/.pyenv/versions/3.10.13/lib/python3.10/site-packages/sklearn/utils/_encode.py", line 174, in <listcomp>
    return xp.asarray([table[v] for v in values], device=device(values))
  File "/Users/anishanand/.pyenv/versions/3.10.13/lib/python3.10/site-packages/sklearn/utils/_encode.py", line 167, in __missing__
    raise KeyError(key)
KeyError: nan

During handling of the above exception, another exception occurred:

Traceback (most recent call last):
  File "/Users/anishanand/JeevaFitApp/lightSgd/incremental.py", line 60, in <module>
    incremental_train_sgd(
  File "/Users/anishanand/JeevaFitApp/lightSgd/incremental.py", line 37, in incremental_train_sgd
    y_new = le_risk.transform(new_df["Risk_Category"])
  File "/Users/anishanand/.pyenv/versions/3.10.13/lib/python3.10/site-packages/sklearn/preprocessing/_label.py", line 134, in transform
    return _encode(y, uniques=self.classes_)
  File "/Users/anishanand/.pyenv/versions/3.10.13/lib/python3.10/site-packages/sklearn/utils/_encode.py", line 237, in _encode
    raise ValueError(f"y contains previously unseen labels: {str(e)}")
ValueError: y contains previously unseen labels: nan
[INFO] Current working directory: /Users/anishanand/JeevaFitApp/lightSgd
[INFO] Training started at 2025-05-23 19:04:03.038870
Traceback (most recent call last):
  File "/Users/anishanand/.pyenv/versions/3.10.13/lib/python3.10/site-packages/pandas/core/indexes/base.py", line 3805, in get_loc
    return self._engine.get_loc(casted_key)
  File "index.pyx", line 167, in pandas._libs.index.IndexEngine.get_loc
  File "index.pyx", line 196, in pandas._libs.index.IndexEngine.get_loc
  File "pandas/_libs/hashtable_class_helper.pxi", line 7081, in pandas._libs.hashtable.PyObjectHashTable.get_item
  File "pandas/_libs/hashtable_class_helper.pxi", line 7089, in pandas._libs.hashtable.PyObjectHashTable.get_item
KeyError: 'Risk_Category'

The above exception was the direct cause of the following exception:

Traceback (most recent call last):
  File "/Users/anishanand/JeevaFitApp/lightSgd/incremental.py", line 60, in <module>
    incremental_train_sgd(
  File "/Users/anishanand/JeevaFitApp/lightSgd/incremental.py", line 37, in incremental_train_sgd
    y_new = le_risk.transform(new_df["Risk_Category"])
  File "/Users/anishanand/.pyenv/versions/3.10.13/lib/python3.10/site-packages/pandas/core/frame.py", line 4102, in __getitem__
    indexer = self.columns.get_loc(key)
  File "/Users/anishanand/.pyenv/versions/3.10.13/lib/python3.10/site-packages/pandas/core/indexes/base.py", line 3812, in get_loc
    raise KeyError(key) from err
KeyError: 'Risk_Category'
[INFO] Current working directory: /Users/anishanand/JeevaFitApp/lightSgd
[INFO] Training started at 2025-05-23 19:06:02.561025
Traceback (most recent call last):
  File "/Users/anishanand/.pyenv/versions/3.10.13/lib/python3.10/site-packages/pandas/core/indexes/base.py", line 3805, in get_loc
    return self._engine.get_loc(casted_key)
  File "index.pyx", line 167, in pandas._libs.index.IndexEngine.get_loc
  File "index.pyx", line 196, in pandas._libs.index.IndexEngine.get_loc
  File "pandas/_libs/hashtable_class_helper.pxi", line 7081, in pandas._libs.hashtable.PyObjectHashTable.get_item
  File "pandas/_libs/hashtable_class_helper.pxi", line 7089, in pandas._libs.hashtable.PyObjectHashTable.get_item
KeyError: 'Risk_Category'

The above exception was the direct cause of the following exception:

Traceback (most recent call last):
  File "/Users/anishanand/JeevaFitApp/lightSgd/incremental.py", line 60, in <module>
    incremental_train_sgd(
  File "/Users/anishanand/JeevaFitApp/lightSgd/incremental.py", line 37, in incremental_train_sgd
    y_new = le_risk.transform(new_df["Risk_Category"])
  File "/Users/anishanand/.pyenv/versions/3.10.13/lib/python3.10/site-packages/pandas/core/frame.py", line 4102, in __getitem__
    indexer = self.columns.get_loc(key)
  File "/Users/anishanand/.pyenv/versions/3.10.13/lib/python3.10/site-packages/pandas/core/indexes/base.py", line 3812, in get_loc
    raise KeyError(key) from err
KeyError: 'Risk_Category'
[INFO] Current working directory: /Users/anishanand/JeevaFitApp/lightSgd
[INFO] Training started at 2025-05-23 19:08:03.285071
Traceback (most recent call last):
  File "/Users/anishanand/.pyenv/versions/3.10.13/lib/python3.10/site-packages/sklearn/utils/_encode.py", line 235, in _encode
    return _map_to_integer(values, uniques)
  File "/Users/anishanand/.pyenv/versions/3.10.13/lib/python3.10/site-packages/sklearn/utils/_encode.py", line 174, in _map_to_integer
    return xp.asarray([table[v] for v in values], device=device(values))
  File "/Users/anishanand/.pyenv/versions/3.10.13/lib/python3.10/site-packages/sklearn/utils/_encode.py", line 174, in <listcomp>
    return xp.asarray([table[v] for v in values], device=device(values))
  File "/Users/anishanand/.pyenv/versions/3.10.13/lib/python3.10/site-packages/sklearn/utils/_encode.py", line 167, in __missing__
    raise KeyError(key)
KeyError: nan

During handling of the above exception, another exception occurred:

Traceback (most recent call last):
  File "/Users/anishanand/JeevaFitApp/lightSgd/incremental.py", line 60, in <module>
    incremental_train_sgd(
  File "/Users/anishanand/JeevaFitApp/lightSgd/incremental.py", line 37, in incremental_train_sgd
    y_new = le_risk.transform(new_df["Risk_Category"])
  File "/Users/anishanand/.pyenv/versions/3.10.13/lib/python3.10/site-packages/sklearn/preprocessing/_label.py", line 134, in transform
    return _encode(y, uniques=self.classes_)
  File "/Users/anishanand/.pyenv/versions/3.10.13/lib/python3.10/site-packages/sklearn/utils/_encode.py", line 237, in _encode
    raise ValueError(f"y contains previously unseen labels: {str(e)}")
ValueError: y contains previously unseen labels: nan
[INFO] Current working directory: /Users/anishanand/JeevaFitApp/lightSgd
[INFO] Training started at 2025-05-23 19:10:03.241161
Traceback (most recent call last):
  File "/Users/anishanand/.pyenv/versions/3.10.13/lib/python3.10/site-packages/sklearn/utils/_encode.py", line 235, in _encode
    return _map_to_integer(values, uniques)
  File "/Users/anishanand/.pyenv/versions/3.10.13/lib/python3.10/site-packages/sklearn/utils/_encode.py", line 174, in _map_to_integer
    return xp.asarray([table[v] for v in values], device=device(values))
  File "/Users/anishanand/.pyenv/versions/3.10.13/lib/python3.10/site-packages/sklearn/utils/_encode.py", line 174, in <listcomp>
    return xp.asarray([table[v] for v in values], device=device(values))
  File "/Users/anishanand/.pyenv/versions/3.10.13/lib/python3.10/site-packages/sklearn/utils/_encode.py", line 167, in __missing__
    raise KeyError(key)
KeyError: nan

During handling of the above exception, another exception occurred:

Traceback (most recent call last):
  File "/Users/anishanand/JeevaFitApp/lightSgd/incremental.py", line 60, in <module>
    incremental_train_sgd(
  File "/Users/anishanand/JeevaFitApp/lightSgd/incremental.py", line 37, in incremental_train_sgd
    y_new = le_risk.transform(new_df["Risk_Category"])
  File "/Users/anishanand/.pyenv/versions/3.10.13/lib/python3.10/site-packages/sklearn/preprocessing/_label.py", line 134, in transform
    return _encode(y, uniques=self.classes_)
  File "/Users/anishanand/.pyenv/versions/3.10.13/lib/python3.10/site-packages/sklearn/utils/_encode.py", line 237, in _encode
    raise ValueError(f"y contains previously unseen labels: {str(e)}")
ValueError: y contains previously unseen labels: nan
[INFO] Current working directory: /Users/anishanand/JeevaFitApp/lightSgd
[INFO] Training started at 2025-05-23 19:12:03.017043
Traceback (most recent call last):
  File "/Users/anishanand/.pyenv/versions/3.10.13/lib/python3.10/site-packages/sklearn/utils/_encode.py", line 235, in _encode
    return _map_to_integer(values, uniques)
  File "/Users/anishanand/.pyenv/versions/3.10.13/lib/python3.10/site-packages/sklearn/utils/_encode.py", line 174, in _map_to_integer
    return xp.asarray([table[v] for v in values], device=device(values))
  File "/Users/anishanand/.pyenv/versions/3.10.13/lib/python3.10/site-packages/sklearn/utils/_encode.py", line 174, in <listcomp>
    return xp.asarray([table[v] for v in values], device=device(values))
  File "/Users/anishanand/.pyenv/versions/3.10.13/lib/python3.10/site-packages/sklearn/utils/_encode.py", line 167, in __missing__
    raise KeyError(key)
KeyError: nan

During handling of the above exception, another exception occurred:

Traceback (most recent call last):
  File "/Users/anishanand/JeevaFitApp/lightSgd/incremental.py", line 60, in <module>
    incremental_train_sgd(
  File "/Users/anishanand/JeevaFitApp/lightSgd/incremental.py", line 37, in incremental_train_sgd
    y_new = le_risk.transform(new_df["Risk_Category"])
  File "/Users/anishanand/.pyenv/versions/3.10.13/lib/python3.10/site-packages/sklearn/preprocessing/_label.py", line 134, in transform
    return _encode(y, uniques=self.classes_)
  File "/Users/anishanand/.pyenv/versions/3.10.13/lib/python3.10/site-packages/sklearn/utils/_encode.py", line 237, in _encode
    raise ValueError(f"y contains previously unseen labels: {str(e)}")
ValueError: y contains previously unseen labels: nan
[INFO] Current working directory: /Users/anishanand/JeevaFitApp/lightSgd
[INFO] Training started at 2025-05-23 19:14:02.859371
Traceback (most recent call last):
  File "/Users/anishanand/JeevaFitApp/lightSgd/incremental.py", line 62, in <module>
    incremental_train_sgd(
  File "/Users/anishanand/JeevaFitApp/lightSgd/incremental.py", line 13, in incremental_train_sgd
    new_df.columns = [col.replace(" ", "_") for col in new_df.columns]
UnboundLocalError: local variable 'new_df' referenced before assignment
[INFO] Current working directory: /Users/anishanand/JeevaFitApp/lightSgd
[INFO] Training started at 2025-05-23 19:16:02.668912
Traceback (most recent call last):
  File "/Users/anishanand/JeevaFitApp/lightSgd/incremental.py", line 62, in <module>
    incremental_train_sgd(
  File "/Users/anishanand/JeevaFitApp/lightSgd/incremental.py", line 13, in incremental_train_sgd
    new_df.columns = [col.replace(" ", "_") for col in new_df.columns]
UnboundLocalError: local variable 'new_df' referenced before assignment
[INFO] Current working directory: /Users/anishanand/JeevaFitApp/lightSgd
[INFO] Training started at 2025-05-23 19:18:03.650757
Traceback (most recent call last):
  File "/Users/anishanand/JeevaFitApp/lightSgd/incremental.py", line 62, in <module>
    incremental_train_sgd(
  File "/Users/anishanand/JeevaFitApp/lightSgd/incremental.py", line 13, in incremental_train_sgd
    new_df.columns = [col.replace(" ", "_") for col in new_df.columns]
UnboundLocalError: local variable 'new_df' referenced before assignment
[INFO] Current working directory: /Users/anishanand/JeevaFitApp/lightSgd
[INFO] Training started at 2025-05-23 19:20:03.557786
Traceback (most recent call last):
  File "/Users/anishanand/.pyenv/versions/3.10.13/lib/python3.10/site-packages/sklearn/utils/_encode.py", line 235, in _encode
    return _map_to_integer(values, uniques)
  File "/Users/anishanand/.pyenv/versions/3.10.13/lib/python3.10/site-packages/sklearn/utils/_encode.py", line 174, in _map_to_integer
    return xp.asarray([table[v] for v in values], device=device(values))
  File "/Users/anishanand/.pyenv/versions/3.10.13/lib/python3.10/site-packages/sklearn/utils/_encode.py", line 174, in <listcomp>
    return xp.asarray([table[v] for v in values], device=device(values))
  File "/Users/anishanand/.pyenv/versions/3.10.13/lib/python3.10/site-packages/sklearn/utils/_encode.py", line 167, in __missing__
    raise KeyError(key)
KeyError: nan

During handling of the above exception, another exception occurred:

Traceback (most recent call last):
  File "/Users/anishanand/JeevaFitApp/lightSgd/incremental.py", line 62, in <module>
    incremental_train_sgd(
  File "/Users/anishanand/JeevaFitApp/lightSgd/incremental.py", line 39, in incremental_train_sgd
    y_new = le_risk.transform(new_df["Risk_Category"])
  File "/Users/anishanand/.pyenv/versions/3.10.13/lib/python3.10/site-packages/sklearn/preprocessing/_label.py", line 134, in transform
    return _encode(y, uniques=self.classes_)
  File "/Users/anishanand/.pyenv/versions/3.10.13/lib/python3.10/site-packages/sklearn/utils/_encode.py", line 237, in _encode
    raise ValueError(f"y contains previously unseen labels: {str(e)}")
ValueError: y contains previously unseen labels: nan
[INFO] Current working directory: /Users/anishanand/JeevaFitApp/lightSgd
[INFO] Training started at 2025-05-23 19:22:03.457334
Traceback (most recent call last):
  File "/Users/anishanand/.pyenv/versions/3.10.13/lib/python3.10/site-packages/sklearn/utils/_encode.py", line 235, in _encode
    return _map_to_integer(values, uniques)
  File "/Users/anishanand/.pyenv/versions/3.10.13/lib/python3.10/site-packages/sklearn/utils/_encode.py", line 174, in _map_to_integer
    return xp.asarray([table[v] for v in values], device=device(values))
  File "/Users/anishanand/.pyenv/versions/3.10.13/lib/python3.10/site-packages/sklearn/utils/_encode.py", line 174, in <listcomp>
    return xp.asarray([table[v] for v in values], device=device(values))
  File "/Users/anishanand/.pyenv/versions/3.10.13/lib/python3.10/site-packages/sklearn/utils/_encode.py", line 167, in __missing__
    raise KeyError(key)
KeyError: nan

During handling of the above exception, another exception occurred:

Traceback (most recent call last):
  File "/Users/anishanand/JeevaFitApp/lightSgd/incremental.py", line 62, in <module>
    incremental_train_sgd(
  File "/Users/anishanand/JeevaFitApp/lightSgd/incremental.py", line 39, in incremental_train_sgd
    y_new = le_risk.transform(new_df["Risk_Category"])
  File "/Users/anishanand/.pyenv/versions/3.10.13/lib/python3.10/site-packages/sklearn/preprocessing/_label.py", line 134, in transform
    return _encode(y, uniques=self.classes_)
  File "/Users/anishanand/.pyenv/versions/3.10.13/lib/python3.10/site-packages/sklearn/utils/_encode.py", line 237, in _encode
    raise ValueError(f"y contains previously unseen labels: {str(e)}")
ValueError: y contains previously unseen labels: nan
[INFO] Current working directory: /Users/anishanand/JeevaFitApp/lightSgd
[INFO] Training started at 2025-05-23 19:24:03.412277
[INFO] Unique labels in new data: ['High Risk']
Traceback (most recent call last):
  File "/Users/anishanand/JeevaFitApp/lightSgd/incremental.py", line 97, in <module>
    incremental_train_sgd(
  File "/Users/anishanand/JeevaFitApp/lightSgd/incremental.py", line 77, in incremental_train_sgd
    sgd_model.partial_fit(X_new_scaled, y_new, classes=classes)
  File "/Users/anishanand/.pyenv/versions/3.10.13/lib/python3.10/site-packages/sklearn/base.py", line 1389, in wrapper
    return fit_method(estimator, *args, **kwargs)
  File "/Users/anishanand/.pyenv/versions/3.10.13/lib/python3.10/site-packages/sklearn/linear_model/_stochastic_gradient.py", line 875, in partial_fit
    raise ValueError(
ValueError: class_weight 'balanced' is not supported for partial_fit. In order to use 'balanced' weights, use compute_class_weight('balanced', classes=classes, y=y). In place of y you can use a large enough sample of the full training set target to properly estimate the class frequency distributions. Pass the resulting weights as the class_weight parameter.
[INFO] Current working directory: /Users/anishanand/JeevaFitApp/lightSgd
[INFO] Training started at 2025-05-23 19:26:03.258675
[INFO] Unique labels in new data: ['High Risk']
Traceback (most recent call last):
  File "/Users/anishanand/JeevaFitApp/lightSgd/incremental.py", line 97, in <module>
    incremental_train_sgd(
  File "/Users/anishanand/JeevaFitApp/lightSgd/incremental.py", line 77, in incremental_train_sgd
    sgd_model.partial_fit(X_new_scaled, y_new, classes=classes)
  File "/Users/anishanand/.pyenv/versions/3.10.13/lib/python3.10/site-packages/sklearn/base.py", line 1389, in wrapper
    return fit_method(estimator, *args, **kwargs)
  File "/Users/anishanand/.pyenv/versions/3.10.13/lib/python3.10/site-packages/sklearn/linear_model/_stochastic_gradient.py", line 875, in partial_fit
    raise ValueError(
ValueError: class_weight 'balanced' is not supported for partial_fit. In order to use 'balanced' weights, use compute_class_weight('balanced', classes=classes, y=y). In place of y you can use a large enough sample of the full training set target to properly estimate the class frequency distributions. Pass the resulting weights as the class_weight parameter.
[INFO] Current working directory: /Users/anishanand/JeevaFitApp/lightSgd
[INFO] Training started at 2025-05-23 19:28:02.880044
[ERROR] Label encoding error: y contains previously unseen labels: 'nan'
[INFO] Current working directory: /Users/anishanand/JeevaFitApp/lightSgd
[INFO] Training started at 2025-05-23 19:30:02.807965
[ERROR] Label encoding error: y contains previously unseen labels: 'nan'
[INFO] Current working directory: /Users/anishanand/JeevaFitApp/lightSgd
[INFO] Training started at 2025-05-23 19:32:02.812250
[ERROR] Label encoding error: y contains previously unseen labels: 'nan'
[INFO] Current working directory: /Users/anishanand/JeevaFitApp/lightSgd
[INFO] Training started at 2025-05-23 19:34:02.714361
[ERROR] Label encoding error: y contains previously unseen labels: 'nan'
[INFO] Current working directory: /Users/anishanand/JeevaFitApp/lightSgd
[INFO] Training started at 2025-05-23 19:36:01.856215
[ERROR] Label encoding error: y contains previously unseen labels: 'nan'
[INFO] Current working directory: /Users/anishanand/JeevaFitApp/lightSgd
[INFO] Training started at 2025-05-23 19:38:02.830098
[ERROR] Label encoding error: y contains previously unseen labels: 'nan'
[INFO] Current working directory: /Users/anishanand/JeevaFitApp/lightSgd
[INFO] Training started at 2025-05-23 19:40:03.258712
[ERROR] Label encoding error: y contains previously unseen labels: 'nan'
[INFO] Current working directory: /Users/anishanand/JeevaFitApp/lightSgd
[INFO] Training started at 2025-05-23 19:42:02.845272
[ERROR] Label encoding error: y contains previously unseen labels: 'nan'
[INFO] Current working directory: /Users/anishanand/JeevaFitApp/lightSgd
[INFO] Training started at 2025-05-23 19:44:02.730502
[ERROR] Label encoding error: y contains previously unseen labels: 'nan'
[INFO] Current working directory: /Users/anishanand/JeevaFitApp/lightSgd
[INFO] Training started at 2025-05-23 19:46:02.634686
[ERROR] Label encoding error: y contains previously unseen labels: 'nan'
[INFO] Current working directory: /Users/anishanand/JeevaFitApp/lightSgd
[INFO] Training started at 2025-05-23 19:48:03.355713
[ERROR] Unseen Risk_Category labels found in new data: {'nan'}. Exiting.
[INFO] Current working directory: /Users/anishanand/JeevaFitApp/lightSgd
[INFO] Training started at 2025-05-23 19:50:03.241580
[ERROR] Unseen Risk_Category labels found in new data: {'nan'}. Exiting.
[INFO] Current working directory: /Users/anishanand/JeevaFitApp/lightSgd
[INFO] Training started at 2025-05-23 19:52:03.111946
[ERROR] Unseen Risk_Category labels found in new data: {'nan'}. Exiting.
[INFO] Current working directory: /Users/anishanand/JeevaFitApp/lightSgd
[INFO] Training started at 2025-05-23 19:54:03.001836
[ERROR] Unseen Risk_Category labels found in new data: {'nan'}. Exiting.
[INFO] Current working directory: /Users/anishanand/JeevaFitApp/lightSgd
[INFO] Training started at 2025-05-23 19:56:03.064711
[ERROR] Unseen Risk_Category labels found in new data: {'nan'}. Exiting.
[INFO] Current working directory: /Users/anishanand/JeevaFitApp/lightSgd
[INFO] Training started at 2025-05-23 19:58:02.967134
[INFO] Accuracy on incremental batch: 1.0000
Traceback (most recent call last):
  File "/Users/anishanand/JeevaFitApp/lightSgd/incremental.py", line 118, in <module>
    incremental_train_sgd(
  File "/Users/anishanand/JeevaFitApp/lightSgd/incremental.py", line 108, in incremental_train_sgd
    report = classification_report(y_new, y_pred, target_names=le_risk.classes_)
  File "/Users/anishanand/.pyenv/versions/3.10.13/lib/python3.10/site-packages/sklearn/utils/_param_validation.py", line 216, in wrapper
    return func(*args, **kwargs)
  File "/Users/anishanand/.pyenv/versions/3.10.13/lib/python3.10/site-packages/sklearn/metrics/_classification.py", line 2693, in classification_report
    raise ValueError(
ValueError: Number of classes, 1, does not match size of target_names, 2. Try specifying the labels parameter
[INFO] Current working directory: /Users/anishanand/JeevaFitApp/lightSgd
[INFO] Training started at 2025-05-23 20:00:03.017625
[INFO] Accuracy on incremental batch: 1.0000
Traceback (most recent call last):
  File "/Users/anishanand/JeevaFitApp/lightSgd/incremental.py", line 118, in <module>
    incremental_train_sgd(
  File "/Users/anishanand/JeevaFitApp/lightSgd/incremental.py", line 108, in incremental_train_sgd
    report = classification_report(y_new, y_pred, target_names=le_risk.classes_)
  File "/Users/anishanand/.pyenv/versions/3.10.13/lib/python3.10/site-packages/sklearn/utils/_param_validation.py", line 216, in wrapper
    return func(*args, **kwargs)
  File "/Users/anishanand/.pyenv/versions/3.10.13/lib/python3.10/site-packages/sklearn/metrics/_classification.py", line 2693, in classification_report
    raise ValueError(
ValueError: Number of classes, 1, does not match size of target_names, 2. Try specifying the labels parameter
[INFO] Current working directory: /Users/anishanand/JeevaFitApp/lightSgd
[INFO] Training started at 2025-05-23 20:02:03.120992
[INFO] Accuracy on incremental batch: 1.0000
[INFO] Classification Report on incremental batch:
              precision    recall  f1-score   support

   High Risk       1.00      1.00      1.00         7
    Low Risk       1.00      1.00      1.00         5

    accuracy                           1.00        12
   macro avg       1.00      1.00      1.00        12
weighted avg       1.00      1.00      1.00        12

[INFO] Incrementally trained SGD model with 12 new samples.
[INFO] Training finished at 2025-05-23 20:02:03.306826
[INFO] Current working directory: /Users/anishanand/JeevaFitApp/lightSgd
[INFO] Training started at 2025-05-23 20:04:03.215622
[INFO] Accuracy on incremental batch: 1.0000
[INFO] Classification Report on incremental batch:
              precision    recall  f1-score   support

   High Risk       1.00      1.00      1.00         7
    Low Risk       1.00      1.00      1.00         5

    accuracy                           1.00        12
   macro avg       1.00      1.00      1.00        12
weighted avg       1.00      1.00      1.00        12

[INFO] Incrementally trained SGD model with 12 new samples.
[INFO] Training finished at 2025-05-23 20:04:03.404758
[INFO] Current working directory: /Users/anishanand/JeevaFitApp/lightSgd
[INFO] Training started at 2025-05-23 20:06:02.995018
[INFO] Accuracy on incremental batch: 1.0000
[INFO] Classification Report on incremental batch:
              precision    recall  f1-score   support

   High Risk       1.00      1.00      1.00         7
    Low Risk       1.00      1.00      1.00         5

    accuracy                           1.00        12
   macro avg       1.00      1.00      1.00        12
weighted avg       1.00      1.00      1.00        12

[INFO] Incrementally trained SGD model with 12 new samples.
[INFO] Training finished at 2025-05-23 20:06:03.162759
